Workbook
Name \A: [1]A!$D$9:$D$53
Name ____MES1: '[2]DATOS DE OBRA'!#REF!
Name ___MES1: '[3]DATOS DE OBRA'!#REF!
Name ___PAG1: #REF!
Name __MES1: '[4]DATOS DE OBRA'!#REF!
Name __PAG1: #REF!
Name _MES1: '[3]DATOS DE OBRA'!#REF!
Name _MET1: #REF!
Name _MET2: #REF!
Name _PAG1: #REF!
Name A: [5]AreaLaguna!#REF!
Name A_1: #REF!
Name A_10: #REF!
Name A_11: #REF!
Name A_12: #REF!
Name A_13: #REF!
Name A_14: #REF!
Name A_15: #REF!
Name A_16: #REF!
Name A_17: #REF!
Name A_18: #REF!
Name A_19: #REF!
Name A_2: #REF!
Name A_20: #REF!
Name A_21: #REF!
Name A_22: #REF!
Name A_3: #REF!
Name A_4: #REF!
Name A_5: #REF!
Name A_6: #REF!
Name A_7: #REF!
Name A_8: #REF!
Name A_9: #REF!
Name A_impresión_IM: [6]Lagsram2!#REF!
Name aA: #REF!
Name aAA: #REF!
Name aB: #REF!
Name aC: #REF!
Name ACE: [1]A!$D$38
Name ACERO: [1]A!$D$70:$D$71
Name ACOM_CC: #REF!
Name ACOM_SC: #REF!
Name aD: #REF!
Name ADICIONAL: #REF!
Name ARENA: [1]A!$D$55:$D$56
Name ARMADOS: #REF!
Name ASAS: #REF!
Name BO_ACERO: [1]A!$D$37
Name BO_ARENA: [1]A!$D$21
Name BO_CEMENTO: [1]A!$D$27
Name BO_FORMALETA: [1]A!$D$33
Name BO_GRAVA: [1]A!$D$24
Name BO_OTROS: [1]A!$D$30
Name BO_SUMINISTRO: [1]A!$D$41
Name Cambio: #REF!
Name CAP: #REF!
Name CEMENTO: [1]A!$D$61:$D$62
Name CONDUC: #REF!
Name CONTRATISTA: CONCATENATE(": ",[8]FICHA!$E$8)
Name Costos: #REF!

Sheet RES. VALO
B2: RESUMEN DE LA VALORIZACIÓN N° 03 (01 AL 31 DE DICIEMBRE 2025)
B4: OBRA: | C4: =+FICHA!E4 -> "CONSTRUCCION DE NICHO, COLUMBARIO Y CREMATORIO; REMODELACION DE VELATORIO; EN EL (LA) CEMENTERIO MUNICIPAL EN EL CENTRO POBLADO SANTIAGO DE SURCO, DISTRITO DE SANTIAGO DE SURCO, PROVINCIA LIMA, DEPARTAMENTO LIMA" CUI N| 2658565 - ETAPA COLUMBARIO.
B5: UBICACIÓN: | C5: SURCO PUEBLO
B6: CONTRATISTA: | C6: CONSORCIO LIMA
B7: SUPERVISIÓN: | C7: ING. JOSE ISMAEL MOSCOSO PINGO
B8: MES: | C8: 45962
B10: ITEM | C10: CONCEPTOS | D10: MONTO (S/.)
B11: 1 | C11: VALORIZACIÓN (V) | D11: =+VALO!K565 -> 207432.97
B12: 2 | C12: REAJUSTES (R) | D12: =+Reajuste!J25 -> 0
B13: 3 | C13: DEDUCCIONES
B14: 3.1 | C14: Deducción de reajuste que no corresponde por adelanto directo | D14: 0
B15: 3.2 | C15: Deducción de reajuste que no corresponde por adelanto para materiales | D15: 0
C16: TOTAL DEDUCCIONES (D) | D16: =+D14+D15 -> 0
C17: VALORIZACIÓN BRUTA (VB=V+R-D) | D17: =+D11+D12-D16 -> 207432.97
B18: 4 | C18: AMORTIZACIONES
B19: 4.1 | C19: Amortización por adelanto directo | D19: 0
B20: 4.2 | C20: Amortización por adelanto para materiales | D20: 0
C21: TOTAL DE AMORTIZACIONES (A) | D21: =ROUND(D19+D20,2) -> 0
B22: VALORIZACIÓN NETA (VN=VB-A) | D22: =ROUND(D17-D21,2) -> 207432.97
B23: 5.1 | C23: MULTA | D23: 0
B24: 5.2 | C24: MONTO A PAGAR A LA CONTRATISTA | D24: =+D22 -> 207432.97
B25: IGV (18.00%) | D25: =+ROUND(D24*0.18,2) -> 37337.93
C26: MONTO TOTAL A PAGAR AL CONTRATISTA | D26: =+D24+D25 -> 244770.9
B27: 5.3 | C27: RETENCIONES 10 % (YA SE COMPLETÓ) | D27: 0
B28: TOTAL A PAGAR AL CONTRATISTA (VN+IGV-R) | D28: =+D24+D25-D27 -> 244770.9
C31: perfecto VLIZACION 01

Sheet FICHA
B2: I.- FICHA DE IDENTIFICACIÓN DE LA OBRA
B3: VALORIZACIÓN CONTRACTUAL DE OBRA Nº 03 (01 al 31 de DICIEMBRE) | E3: DICIEMBRE 2025
B4: 1 | C4: Proyecto | D4: : | E4: "CONSTRUCCION DE NICHO, COLUMBARIO Y CREMATORIO; REMODELACION DE VELATORIO; EN EL (LA) CEMENTERIO MUNICIPAL EN EL CENTRO POBLADO SANTIAGO DE SURCO, DISTRITO DE SANTIAGO DE SURCO, PROVINCIA LIMA, DEPARTAMENTO LIMA" CUI N| 2658565 - ETAPA COLUMBARIO.
B5: 2 | C5: Ubicación | D5: : | E5: DISTRITO DE SANTIAGO DE SURCO
C6: Area Geografica (Según INEI) | D6: : | E6: 2
B7: 3 | C7: Metas | D7: : | E7: CONSTRUCCION DE CREMATORIO, COLUMBARIO Y VELATORIO EN EL CEMENTERIO MUNICIPAL DE SURCO
B8: 4 | C8: Entidad Contratante | D8: : | E8: MUNICIPALIDAD DISTRITAL DE SANTIAGO DE SURCO
B9: 5 | C9: Contratista | D9: : | E9: CONSORCIO LIMA
B10: =+B9+1 -> 6 | C10: Supervisor | D10: : | E10: ING. JOSE ISMAEL MOSCOSO PINGO | G10: CIP N°259230
B11: =+B10+1 -> 7 | C11: Residente | D11: : | E11: ING. GUIDO JAVIER VALVERDE TRUJILLO | G11: CIP N° 58998
B12: =+B11+1 -> 8 | C12: Financiamiento | D12: : | E12: =+E8 -> MUNICIPALIDAD DISTRITAL DE SANTIAGO DE SURCO
B13: =+B12+1 -> 9 | C13: Modalidad de Ejecución | D13: : | E13: Administración Indirecta: CONTRATA
B14: =+B13+1 -> 10 | C14: Mecanismo de Contratación | D14: : | E14: ADJUDICACION PUBLICA ABREVIADA
B15: =+B14+1 -> 11 | C15: Licitiación Pública | D15: : | E15: 004-2025-CS-MSS-PRIMERA CONVOCATORIA
B16: =+B15+1 -> 12 | C16: Contrato Nº | D16: : | E16: 037-2025-GAF/MSS
B17: =+B16+1 -> 13 | C17: Sistema de Contratación | D17: : | E17: SUMA ALZADA
B18: =+B17+1 -> 14 | C18: Presupuesto base, con IGV y Fecha | D18: : | E18: 1821179.8 | G18: 45809
B19: =+B18+1 -> 15 | C19: Presupuesto base, sin IGV y Fecha | D19: : | E19: =E18/1.18 -> 1543372.7
B20: 16 | C20: Monto del contrato, con IGV | D20: : | E20: 1730120.8
B21: =+B20+1 -> 17 | C21: Monto del contrato, sin IGV | D21: : | E21: =ROUND(E20/1.18,2) -> 1466204.1
B22: =+B21+1 -> 18 | C22: Plazo de ejecución, en d. c. | D22: : | E22: 120
B23: =+B22+1 -> 19 | C23: Plazo de ejecución según Bases Lic., en dias calendario | D23: : | E23: =E22&" Días Calendario" -> 120 Días Calendario
B24: 20 | C24: Fecha de Firma de Contrato de obra | D24: : | E24: 45937
B25: =+B24+1 -> 21 | C25: Entrega de terreno | D25: : | E25: 45948
B26: =+B25+1 -> 22 | C26: Inicio oficial de plazo | D26: : | E26: 45954
B27: =+B26+1 -> 23 | C27: Término original programado de obra | D27: : | E27: =E26+E22-1 -> 46073
B28: =+B27+1 -> 24 | C28: Término vigente programado de obra | D28: : | E28: =E26+E22-1 -> 46073
B29: =+B28+1 -> 25 | C29: Avance Real Acumulado | D29: : | E29: =+VALO!N570 -> 0.72547563
B30: =+B29+1 -> 26 | C30: Avance Programado Acumulado | D30: : | E30: =+'C.G. AVANCE DE OBRA'!G16 -> 0.63343707
B31: =+B30+1 -> 27 | C31: Situación de la obra respecto del avance | D31: : | E31: =IF(E29>E30,"OBRA ADELANTADA",IF(E29=E30,"OBRA TERMINADA","OBRA ATRASADA")) -> OBRA ADELANTADA | F31: =ABS(E29-E30) -> 0.092038563
B38: PERFECTOOO

Sheet C.G. AVANCE DE OBRA
B2: CONTROL GENERAL DE AVANCE DE OBRA (01 AL 31 DE DICIEMBRE)
B5: ENTIDAD | C5: MUNICIPALIDAD DISTRITAL DE SANTIAGO DE SURCO | I5: MONTO REFERENCIAL | J5: =+FICHA!E18 -> 1821179.8
B6: CONTRATO DE OBRA | C6: =+FICHA!E16 -> 037-2025-GAF/MSS | I6: MONTO CONTRATADO | J6: =+FICHA!E20 -> 1730120.8
B7: OBRA | C7: =+FICHA!E4 -> "CONSTRUCCION DE NICHO, COLUMBARIO Y CREMATORIO; REMODELACION DE VELATORIO; EN EL (LA) CEMENTERIO MUNICIPAL EN EL CENTRO POBLADO SANTIAGO DE SURCO, DISTRITO DE SANTIAGO DE SURCO, PROVINCIA LIMA, DEPARTAMENTO LIMA" CUI N| 2658565 - ETAPA COLUMBARIO. | I7: PLAZO DE EJECUCIÓN VIGENTE | J7: =+FICHA!E23 -> 120 Días Calendario
B8: CONTRATISTA | C8: =+FICHA!E9 -> CONSORCIO LIMA | I8: FCHA DE INICIO DE OBRA | J8: =+FICHA!E26 -> 45954
B9: SUPERVISIÓN | C9: =+FICHA!E10 -> ING. JOSE ISMAEL MOSCOSO PINGO | I9: FECHA DE TERMINO DE OBRA | J9: =+FICHA!E27 -> 46073
B11: N° | C11: MES | D11: PROGRAMADO | H11: EJECUTADO | L11: SITUACIÓN DE OBRA | M11: OBSERVACION
D12: MENSUAL | E12: ACUMULADO | F12: % MENSUAL | G12: % ACUMULADO | H12: MENSUAL | I12: ACUMULADO | J12: % MENSUAL | K12: % ACUMULADO | M12: % PROGRAMADO ACUMULADO | N12: % EJECUTADO ACUMULADO | O12: CONCLUSIÓN
B14: 1 | C14: =+'CURVA S'!E29 -> 45939 | D14: 303729.84 | E14: =+D14 -> 303729.84 | F14: =+D14/$J$6 -> 0.17555412 | G14: =+F14 -> 0.17555412 | H14: 389969.06 | I14: =+H14 -> 389969.06 | J14: 0.2253999 | K14: =+J14 -> 0.2253999 | L14: adelantada | M14: =+G14 -> 0.17555412 | N14: =+K14 -> 0.2253999 | O14: La obra está sin inconveniente
B15: 2 | C15: =+'CURVA S'!E62 -> 45962 | D15: 307642.3 | E15: =+E14+D15 -> 611372.14 | F15: =+D15/$J$6 -> 0.1778155 | G15: =+G14+F15 -> 0.35336962 | H15: 620420.54 | I15: =+I14+H15 -> 1010389.6 | J15: 0.35859954 | K15: =+K14+J15 -> 0.58399944 | L15: adelantada | M15: =+G15 -> 0.35336962 | N15: =+K15 -> 0.58399944 | O15: La obra está sin inconveniente
B16: 3 | C16: =+'CURVA S'!E63 -> 45992 | D16: 484550.53 | E16: =+E15+D16 -> 1095922.7 | F16: =+D16/$J$6 -> 0.28006745 | G16: =+G15+F16 -> 0.63343707 | H16: =+VALO!K568 -> 244770.9 | I16: =+I15+H16 -> 1255160.5 | J16: =+VALO!K569 -> 0.14147619 | K16: =+K15+J16 -> 0.72547563 | L16: adelantada | M16: =+G16 -> 0.63343707 | N16: =+K16 -> 0.72547563 | O16: La obra está sin inconveniente
B17: 4 | C17: =+'CURVA S'!E64 -> 46023 | D17: 374272.7 | E17: =+E16+D17 -> 1470195.4 | F17: =+D17/$J$6 -> 0.21632749 | G17: =+G16+F17 -> 0.84976456
B18: 5 | C18: =+'CURVA S'!E65 -> 46054 | D18: 259925.47 | E18: =+E17+D18 -> 1730120.8 | F18: =+D18/$J$6 -> 0.15023544 | G18: =+G17+F18 -> 1
E24: =+E18*0.3 -> 519036.25

Sheet VALO
A2: VALORIZACIÓN N° 03 (01 AL 31 DE DICIEMBRE DE 2025)
A4: CONTRATISTA | B4: CONSORCIO LIMA | G4: MONTO REFERENCIAL | M4: =+FICHA!E18 -> 1821179.8
A5: SUPERVISIÓN | B5: ING. JOSE ISMAEL MOSCOSO PINGO | G5: MONTO CONTRATADO | M5: 1730120.8
A6: RESIDENTE | B6: ING. GUIDO JAVIER VALVERDE TRUJILLO | G6: PLAZO DE EJECUCION | M6: 120 DÍAS CALENDARIOS
A7: SUPERVISOR | B7: ING. JOSE ISMAEL MOSCOSO PINGO | G7: ENTIDAD CONTRATANTE | M7: MUNICIPALIDAD DISTRITAL DE SANTIAGO DE SURCO
A9: ITEM | B9: PARTIDA | C9: PRESUPUESTO BASE | G9: AVANCE DE EJECUCIÓN
G13: ANTERIOR | J13: ACTUAL | M13: ACUMULADO | P13: SALDOS
C14: UND | D14: METRADO | E14: PU | F14: SUB TOTAL | G14: METRADO | H14: VALOR S/. | I14: % | J14: METRADO | K14: VALOR S/. | L14: % | M14: METRADO | N14: VALOR S/. | O14: % | P14: METRADO | Q14: VALOR S/. | R14: %
A15: 1 | B15: OBRAS PROVISIONALES, TRABAJOS PRELIMINARES, SEGURIDAD Y SALUD | F15: =+F16+F30+F44+F51+F61 -> 77708.1
A16: 01.01 | B16: OBRAS PROVISIONALES | F16: =+F17+F24 -> 16918.48
A17: 01.01.01 | B17: CONSTRUCCIONES PROVISIONALES | F17: =SUM(F18:F23) -> 11209.46
A18: 01.01.01.01 | B18: CARTEL DE IDENTIFICACION DE LA OBRA DE 3.60X2.40 m | C18: und | D18: 1 | E18: 2350.85 | F18: =+ROUND((D18*E18),2) -> 2350.85 | G18: 1 | H18: =G18*E18 -> 2350.85 | I18: =+G18/D18 -> 1 | K18: =J18*E18 -> 0 | L18: =+J18/D18 -> 0 | M18: =+G18+J18 -> 1 | N18: =M18*E18 -> 2350.85 | O18: =+M18/D18 -> 1 | P18: =+D18-M18 -> 0 | Q18: =P18*E18 -> 0 | R18: =+P18/D18 -> 0 | S18: =N18+Q18 -> 2350.85 | T18: =F18-S18 -> 0
A19: 01.01.01.02 | B19: CERCO PERIMETRICO PROVISIONAL DE MALLA RASCHELL H=2.10M | C19: m | D19: 48.86 | E19: 27.65 | F19: =+ROUND((D19*E19),2) -> 1350.98 | G19: 48.86 | H19: =G19*E19 -> 1350.979 | I19: =+G19/D19 -> 1 | K19: =J19*E19 -> 0 | L19: =+J19/D19 -> 0 | M19: =+G19+J19 -> 48.86 | N19: =M19*E19 -> 1350.979 | O19: =+M19/D19 -> 1 | P19: =+D19-M19 -> 0 | Q19: =P19*E19 -> 0 | R19: =+P19/D19 -> 0 | S19: =N19+Q19 -> 1350.979 | T19: =F19-S19 -> 0.001
A20: 01.01.01.03 | B20: CERCO PERIMETRICO PROVISIONAL METALICO H=2.10M PROVISIONAL | C20: m | D20: 48.86 | E20: 42.57 | F20: =+ROUND((D20*E20),2) -> 2079.97 | G20: 48.86 | H20: =G20*E20 -> 2079.9702 | I20: =+G20/D20 -> 1 | K20: =J20*E20 -> 0 | L20: =+J20/D20 -> 0 | M20: =+G20+J20 -> 48.86 | N20: =M20*E20 -> 2079.9702 | O20: =+M20/D20 -> 1 | P20: =+D20-M20 -> 0 | Q20: =P20*E20 -> 0 | R20: =+P20/D20 -> 0 | S20: =N20+Q20 -> 2079.9702 | T20: =F20-S20 -> -0.0002
A21: 01.01.01.04 | B21: ALMACEN, OFICINA Y CASETA DE GUARDIANIA DE TRIPLAY | C21: m2 | D21: 26 | E21: 88.91 | F21: =+ROUND((D21*E21),2) -> 2311.66 | G21: 26 | H21: =G21*E21 -> 2311.66 | I21: =+G21/D21 -> 1 | K21: =J21*E21 -> 0 | L21: =+J21/D21 -> 0 | M21: =+G21+J21 -> 26 | N21: =M21*E21 -> 2311.66 | O21: =+M21/D21 -> 1 | P21: =+D21-M21 -> 0 | Q21: =P21*E21 -> 0 | R21: =+P21/D21 -> 0 | S21: =N21+Q21 -> 2311.66 | T21: =F21-S21 -> 0
A22: 01.01.01.05 | B22: TRANSPORTES DE MAQUINARIAS, EQUIPO Y HERRAMIENTAS A OBRA | C22: glb | D22: 1 | E22: 2280 | F22: =+ROUND((D22*E22),2) -> 2280 | G22: 1 | H22: =G22*E22 -> 2280 | I22: =+G22/D22 -> 1 | K22: =J22*E22 -> 0 | L22: =+J22/D22 -> 0 | M22: =+G22+J22 -> 1 | N22: =M22*E22 -> 2280 | O22: =+M22/D22 -> 1 | P22: =+D22-M22 -> 0 | Q22: =P22*E22 -> 0 | R22: =+P22/D22 -> 0 | S22: =N22+Q22 -> 2280 | T22: =F22-S22 -> 0
A23: 01.01.01.06 | B23: TRANSPORTES DE MATERIALES | C23: glb | D23: 1 | E23: 836 | F23: =+ROUND((D23*E23),2) -> 836 | G23: 1 | H23: =G23*E23 -> 836 | I23: =+G23/D23 -> 1 | K23: =J23*E23 -> 0 | L23: =+J23/D23 -> 0 | M23: =+G23+J23 -> 1 | N23: =M23*E23 -> 836 | O23: =+M23/D23 -> 1 | P23: =+D23-M23 -> 0 | Q23: =P23*E23 -> 0 | R23: =+P23/D23 -> 0 | S23: =N23+Q23 -> 836 | T23: =F23-S23 -> 0
A24: 01.01.02 | B24: INSTALACIONES PROVISIONALES | F24: =SUM(F25:F29) -> 5709.02
A25: 01.01.02.01 | B25: ALQUILER DE BAÑOS QUIMICOS PORTATILES | C25: mes | D25: 4 | E25: 570 | F25: =+ROUND((D25*E25),2) -> 2280 | G25: 2 | H25: =G25*E25 -> 1140 | I25: =+G25/D25 -> 0.5 | J25: 1 | K25: =J25*E25 -> 570 | L25: =+J25/D25 -> 0.25 | M25: =+G25+J25 -> 3 | N25: =M25*E25 -> 1710 | O25: =+M25/D25 -> 0.75 | P25: =+D25-M25 -> 1 | Q25: =P25*E25 -> 570 | R25: =+P25/D25 -> 0.25 | S25: =N25+Q25 -> 2280 | T25: =F25-S25 -> 0
A26: 01.01.02.02 | B26: SUM. E INST. PARA EL PUNTO DE AGUA EN OBRA | C26: glb | D26: 1 | E26: 446.02 | F26: =+ROUND((D26*E26),2) -> 446.02 | G26: 1 | H26: =G26*E26 -> 446.02 | I26: =+G26/D26 -> 1 | K26: =J26*E26 -> 0 | L26: =+J26/D26 -> 0 | M26: =+G26+J26 -> 1 | N26: =M26*E26 -> 446.02 | O26: =+M26/D26 -> 1 | P26: =+D26-M26 -> 0 | Q26: =P26*E26 -> 0 | R26: =+P26/D26 -> 0 | S26: =N26+Q26 -> 446.02 | T26: =F26-S26 -> 0
A27: 01.01.02.03 | B27: SUM. E INST. PARA EL PUNTO DE ENERGIA EN OBRA | C27: glb | D27: 1 | E27: 380 | F27: =+ROUND((D27*E27),2) -> 380 | G27: 1 | H27: =G27*E27 -> 380 | I27: =+G27/D27 -> 1 | K27: =J27*E27 -> 0 | L27: =+J27/D27 -> 0 | M27: =+G27+J27 -> 1 | N27: =M27*E27 -> 380 | O27: =+M27/D27 -> 1 | P27: =+D27-M27 -> 0 | Q27: =P27*E27 -> 0 | R27: =+P27/D27 -> 0 | S27: =N27+Q27 -> 380 | T27: =F27-S27 -> 0
A28: 01.01.02.04 | B28: AGUA PROVISIONAL PARA LA CONSTRUCCION | C28: mes | D28: 4 | E28: 285 | F28: =+ROUND((D28*E28),2) -> 1140 | G28: 2 | H28: =G28*E28 -> 570 | I28: =+G28/D28 -> 0.5 | J28: 1 | K28: =J28*E28 -> 285 | L28: =+J28/D28 -> 0.25 | M28: =+G28+J28 -> 3 | N28: =M28*E28 -> 855 | O28: =+M28/D28 -> 0.75 | P28: =+D28-M28 -> 1 | Q28: =P28*E28 -> 285 | R28: =+P28/D28 -> 0.25 | S28: =N28+Q28 -> 1140 | T28: =F28-S28 -> 0
A29: 01.01.02.05 | B29: ENERGIA ELECTRICA PROVISIONAL | C29: mes | D29: 4 | E29: 365.75 | F29: =+ROUND((D29*E29),2) -> 1463 | G29: 2 | H29: =G29*E29 -> 731.5 | I29: =+G29/D29 -> 0.5 | J29: 1 | K29: =J29*E29 -> 365.75 | L29: =+J29/D29 -> 0.25 | M29: =+G29+J29 -> 3 | N29: =M29*E29 -> 1097.25 | O29: =+M29/D29 -> 0.75 | P29: =+D29-M29 -> 1 | Q29: =P29*E29 -> 365.75 | R29: =+P29/D29 -> 0.25 | S29: =N29+Q29 -> 1463 | T29: =F29-S29 -> 0
A30: 01.02 | B30: TRABAJOS PRELIMINARES | F30: =+F31+F34+F42 -> 4767.26 | T30: =F30-S30 -> #VALUE!
A31: 01.02.01 | B31: CREMATORIO | F31: =SUM(F32:F33) -> 1719.98 | T31: =F31-S31 -> #VALUE!
A32: 01.02.01.01 | B32: DESBROCE Y LIMPIEZA MANUAL DEL TERRENO | C32: m2 | D32: 163 | E32: 5.13 | F32: =+ROUND((D32*E32),2) -> 836.19 | G32: 163 | H32: =G32*E32 -> 836.19 | I32: =+G32/D32 -> 1 | K32: =J32*E32 -> 0 | L32: =+J32/D32 -> 0 | M32: =+G32+J32 -> 163 | N32: =M32*E32 -> 836.19 | O32: =+M32/D32 -> 1 | P32: =+D32-M32 -> 0 | Q32: =P32*E32 -> 0 | R32: =+P32/D32 -> 0 | S32: =N32+Q32 -> 836.19 | T32: =F32-S32 -> 0
A33: 01.02.01.02 | B33: ELIMINACION DE MALEZA Y ARBUSTOS DE FACIL EXTRACCION | C33: m3 | D33: 28.2 | E33: 31.34 | F33: =+ROUND((D33*E33),2) -> 883.79 | G33: 28.2 | H33: =G33*E33 -> 883.788 | I33: =+G33/D33 -> 1 | K33: =J33*E33 -> 0 | L33: =+J33/D33 -> 0 | M33: =+G33+J33 -> 28.2 | N33: =M33*E33 -> 883.788 | O33: =+M33/D33 -> 1 | P33: =+D33-M33 -> 0 | Q33: =P33*E33 -> 0 | R33: =+P33/D33 -> 0 | S33: =N33+Q33 -> 883.788 | T33: =F33-S33 -> 0.002
A34: 01.02.02 | B34: VELATORIO | F34: =SUM(F35:F41) -> 2081.76 | S34: =N34+Q34 -> #VALUE! | T34: =F34-S34 -> #VALUE!
A35: 01.02.02.01 | B35: DEMOLICIÓN DE MUROS EXISTENTES | C35: m2 | D35: 30.39 | E35: 22.14 | F35: =+ROUND((D35*E35),2) -> 672.83 | G35: 30.39 | H35: =G35*E35 -> 672.8346 | I35: =+G35/D35 -> 1 | K35: =J35*E35 -> 0 | L35: =+J35/D35 -> 0 | M35: =+G35+J35 -> 30.39 | N35: =M35*E35 -> 672.8346 | O35: =+M35/D35 -> 1 | P35: =+D35-M35 -> 0 | Q35: =P35*E35 -> 0 | R35: =+P35/D35 -> 0 | S35: =N35+Q35 -> 672.8346 | T35: =F35-S35 -> -0.0046
A36: 01.02.02.02 | B36: DESMONTAJE DE APARATOS SANITARIOS EXISTENTES EN LA OFICINA DE ADMINISTRACIÓN | C36: glb | D36: 1 | E36: 31.49 | F36: =+ROUND((D36*E36),2) -> 31.49 | G36: 1 | H36: =G36*E36 -> 31.49 | I36: =+G36/D36 -> 1 | K36: =J36*E36 -> 0 | L36: =+J36/D36 -> 0 | M36: =+G36+J36 -> 1 | N36: =M36*E36 -> 31.49 | O36: =+M36/D36 -> 1 | P36: =+D36-M36 -> 0 | Q36: =P36*E36 -> 0 | R36: =+P36/D36 -> 0 | S36: =N36+Q36 -> 31.49 | T36: =F36-S36 -> 0
A37: 01.02.02.03 | B37: RETIRO DE CERÁMICO EXISTENTE EN LA OFICINA | C37: m2 | D37: 54.65 | E37: 15.11 | F37: =+ROUND((D37*E37),2) -> 825.76 | G37: 54.65 | H37: =G37*E37 -> 825.7615 | I37: =+G37/D37 -> 1 | K37: =J37*E37 -> 0 | L37: =+J37/D37 -> 0 | M37: =+G37+J37 -> 54.65 | N37: =M37*E37 -> 825.7615 | O37: =+M37/D37 -> 1 | P37: =+D37-M37 -> 0 | Q37: =P37*E37 -> 0 | R37: =+P37/D37 -> 0 | S37: =N37+Q37 -> 825.7615 | T37: =F37-S37 -> -0.0015
A38: 01.02.02.04 | B38: RETIRO DE PISO EXISTENTE EN NUEVA ZONA DE KITCHENETTE Y CANALETAS | C38: m2 | D38: 3.46 | E38: 26.75 | F38: =+ROUND((D38*E38),2) -> 92.56 | G38: 3.46 | H38: =G38*E38 -> 92.555 | I38: =+G38/D38 -> 1 | K38: =J38*E38 -> 0 | L38: =+J38/D38 -> 0 | M38: =+G38+J38 -> 3.46 | N38: =M38*E38 -> 92.555 | O38: =+M38/D38 -> 1 | P38: =+D38-M38 -> 0 | Q38: =P38*E38 -> 0 | R38: =+P38/D38 -> 0 | S38: =N38+Q38 -> 92.555 | T38: =F38-S38 -> 0.005
A39: 01.02.02.05 | B39: DESMONTAJE DE SISTEMAS ELECTRICOS, INC. SELLADO DE SALIDAS SEGÚN PLANO | C39: glb | D39: 1 | E39: 31.49 | F39: =+ROUND((D39*E39),2) -> 31.49 | G39: 1 | H39: =G39*E39 -> 31.49 | I39: =+G39/D39 -> 1 | K39: =J39*E39 -> 0 | L39: =+J39/D39 -> 0 | M39: =+G39+J39 -> 1 | N39: =M39*E39 -> 31.49 | O39: =+M39/D39 -> 1 | P39: =+D39-M39 -> 0 | Q39: =P39*E39 -> 0 | R39: =+P39/D39 -> 0 | S39: =N39+Q39 -> 31.49 | T39: =F39-S39 -> 0
A40: 01.02.02.06 | B40: DESMONTAJE DE SISTEMAS DE COMUNICACIONES Y REDES | C40: glb | D40: 1 | E40: 31.49 | F40: =+ROUND((D40*E40),2) -> 31.49 | G40: 1 | H40: =G40*E40 -> 31.49 | I40: =+G40/D40 -> 1 | K40: =J40*E40 -> 0 | L40: =+J40/D40 -> 0 | M40: =+G40+J40 -> 1 | N40: =M40*E40 -> 31.49 | O40: =+M40/D40 -> 1 | P40: =+D40-M40 -> 0 | Q40: =P40*E40 -> 0 | R40: =+P40/D40 -> 0 | S40: =N40+Q40 -> 31.49 | T40: =F40-S40 -> 0
A41: 01.02.02.07 | B41: ELIMINACION DE MATERIAL EXCEDENTE C/VOLQ. 15M3, D=10km | C41: m3 | D41: 12.64 | E41: 31.34 | F41: =+ROUND((D41*E41),2) -> 396.14 | G41: 12.64 | H41: =G41*E41 -> 396.1376 | I41: =+G41/D41 -> 1 | K41: =J41*E41 -> 0 | L41: =+J41/D41 -> 0 | M41: =+G41+J41 -> 12.64 | N41: =M41*E41 -> 396.1376 | O41: =+M41/D41 -> 1 | P41: =+D41-M41 -> 0 | Q41: =P41*E41 -> 0 | R41: =+P41/D41 -> 0 | S41: =N41+Q41 -> 396.1376 | T41: =F41-S41 -> 0.0024
A42: 01.02.03 | B42: COLUMBARIO | F42: =+F43 -> 965.52
A43: 01.02.03.01 | B43: DESBROCE Y LIMPIEZA MANUAL DEL TERRENO | C43: m2 | D43: 188.21 | E43: 5.13 | F43: =+ROUND((D43*E43),2) -> 965.52 | G43: 188.21 | H43: =G43*E43 -> 965.5173 | I43: =+G43/D43 -> 1 | K43: =J43*E43 -> 0 | L43: =+J43/D43 -> 0 | M43: =+G43+J43 -> 188.21 | N43: =M43*E43 -> 965.5173 | O43: =+M43/D43 -> 1 | P43: =+D43-M43 -> 0 | Q43: =P43*E43 -> 0 | R43: =+P43/D43 -> 0 | S43: =N43+Q43 -> 965.5173 | T43: =F43-S43 -> 0.0027
A44: 1.03 | B44: SEGURIDAD Y SALUD EN EL TRABAJO | F44: =SUM(F45:F50) -> 22523.25
A45: 01.03.01 | B45: ELABORACIÓN, IMPLEMENTACIÓN Y ADMINISTRACIÓN DEL PLAN DE SEGURIDAD Y SALUD EN EL TRABAJO | C45: glb | D45: 1 | E45: 120.76 | F45: =+ROUND((D45*E45),2) -> 120.76 | G45: 1 | H45: =G45*E45 -> 120.76 | I45: =+G45/D45 -> 1 | K45: =J45*E45 -> 0 | L45: =+J45/D45 -> 0 | M45: =+G45+J45 -> 1 | N45: =M45*E45 -> 120.76 | O45: =+M45/D45 -> 1 | P45: =+D45-M45 -> 0 | Q45: =P45*E45 -> 0 | R45: =+P45/D45 -> 0 | S45: =N45+Q45 -> 120.76 | T45: =F45-S45 -> 0
A46: 01.03.02 | B46: EQUIPOS DE PROTECCION INDIVIDUAL | C46: glb | D46: 1 | E46: 10384.45 | F46: =+ROUND((D46*E46),2) -> 10384.45 | G46: 0.5 | H46: =G46*E46 -> 5192.225 | I46: =+G46/D46 -> 0.5 | J46: 0.25 | K46: =J46*E46 -> 2596.1125 | L46: =+J46/D46 -> 0.25 | M46: =+G46+J46 -> 0.75 | N46: =M46*E46 -> 7788.3375 | O46: =+M46/D46 -> 0.75 | P46: =+D46-M46 -> 0.25 | Q46: =P46*E46 -> 2596.1125 | R46: =+P46/D46 -> 0.25 | S46: =N46+Q46 -> 10384.45 | T46: =F46-S46 -> 0
...

Sheet SUSTENTO METRADOS
B2: VALORIZACIÓN N° 02 (PERIODO 01 AL 30 DE NOVIEMBRE 2025)
B3: CONTRATISTA | C3: =+[17]FICHA!E4 -> "CONSTRUCCION DE NICHO, COLUMBARIO Y CREMATORIO; REMODELACION DE VELATORIO; EN EL (LA) CEMENTERIO MUNICIPAL EN EL CENTRO POBLADO SANTIAGO DE SURCO, DISTRITO DE SANTIAGO DE SURCO, PROVINCIA LIMA, DEPARTAMENTO LIMA" CUI N| 2658565 - ETAPA COLUMBARIO.
B4: CONTRATISTA | C4: =+[17]FICHA!E9 -> CONSORCIO LIMA
B5: ENTIDAD | C5: MUNICIPALIDAD DISTRITAL DE SANTIAGO DE SURCO
B6: RESIDENTE | C6: =+[17]FICHA!E11 -> ING. GUIDO JAVIER VALVERDE TRUJILLO
B7: SUPERVISOR | C7: =+[17]FICHA!E10 -> ING. JOSE ISMAEL MOSCOSO PINGO
B8: SUSTENTO DE METRADOS EJECUTADOS DURANTE EL PERIODO
B9: ITEM | C9: DESCRIPCION | D9: UND | E9: LARGO | F9: ANCHO | G9: ALTURA | H9: Nº DE VECES | I9: PARCIAL | J9: TOTAL
B10: 01.01.02 | C10: INSTALACIONES PROVISIONALES
B11: 01.01.02.01 | C11: ALQUILER DE BAÑOS QUIMICOS PORTATILES | D11: mes | J11: 1
B12: 01.01.02.04 | C12: AGUA PROVISIONAL PARA LA CONSTRUCCION | D12: mes | J12: 1
B13: 01.01.02.05 | C13: ENERGIA ELECTRICA PROVISIONAL | D13: mes | J13: 1
B14: 01.02.02 | C14: VELATORIO
B15: 01.02.02.01 | C15: DEMOLICIÓN DE MUROS EXISTENTES | D15: m2 | H15: área = | I15: 30.39 | J15: 30.39
B16: 01.02.02.02 | C16: DESMONTAJE DE APARATOS SANITARIOS EXISTENTES EN LA OFICINA DE ADMINISTRACIÓN | D16: glb | J16: 1
B17: 01.02.02.03 | C17: RETIRO DE CERÁMICO EXISTENTE EN LA OFICINA | D17: m2 | H17: área = | I17: =+J17 -> 54.65 | J17: 54.65
B18: 01.02.02.04 | C18: RETIRO DE PISO EXISTENTE EN NUEVA ZONA DE KITCHENETTE Y CANALETAS | D18: m2 | H18: área = | I18: =+J18 -> 3.46 | J18: 3.46
B19: 01.02.02.05 | C19: DESMONTAJE DE SISTEMAS ELECTRICOS, INC. SELLADO DE SALIDAS SEGÚN PLANO | D19: glb | J19: 1
B20: 01.02.02.06 | C20: DESMONTAJE DE SISTEMAS DE COMUNICACIONES Y REDES | D20: glb | J20: 1
B21: 01.02.02.07 | C21: ELIMINACION DE MATERIAL EXCEDENTE C/VOLQ. 15M3, D=10km | D21: m3 | H21: vol = | I21: =+J21 -> 12.64 | J21: 12.64
B22: 1.03 | C22: SEGURIDAD Y SALUD EN EL TRABAJO
B23: 01.03.02 | C23: EQUIPOS DE PROTECCION INDIVIDUAL | D23: glb | J23: 0.25
B24: 01.03.03 | C24: EQUIPOS DE PROTECCION COLECTIVA | D24: glb | J24: 0.25
B25: 01.03.04 | C25: SEÑALIZACIÓN TEMPORAL DE SEGURIDAD | D25: glb | J25: 0.25
B26: 01.03.05 | C26: CAPACITACION EN SEGURIDAD Y SALUD | D26: glb | J26: 0.25
B27: 01.03.06 | C27: RECURSOS PARA RESPUESTAS ANTE EMERGENCIAS | D27: glb | J27: 0.25
B28: 01.04 | C28: PLAN DE MANEJO AMBIENTAL
B29: 01.04.04 | C29: PROGRAMA DE USO DE AGUA | D29: glb | J29: 0.5
B30: 01.04.05 | C30: PROGRAMA DE EDUCACION, FORMACION Y CAPACITACION DE PERSONAL | D30: glb | J30: 0.5
B31: 01.04.06 | C31: PROGRAMA DE SEGURIDAD Y SALUD OCUPACIONAL | D31: glb | J31: 0.5
B32: 01.04.07 | C32: PLAN DE CONTINGENCIAS | D32: glb | J32: 0.5
B33: 01.05 | C33: TRAZO Y REPLANTEO
B34: 01.05.02 | C34: TRAZO NIVELACION Y REPLANTEO DURANTE EL PROCESO | D34: m2 | H34: área = | I34: =+J34 -> 101.28 | J34: 101.28
B35: 2 | C35: ESTRUCTURAS
B36: 02.01 | C36: CREMATORIO
B37: 02.01.01 | C37: MOVIMIENTO DE TIERRAS
B38: 02.01.01.08 | C38: RELLENO CON MATERIAL DE PRESTAMO (AFIRMADO) | D38: m3 | H38: vol = | I38: =+J38 -> 76.9 | J38: 76.9
B39: 02.01.02 | C39: OBRAS DE CONCRETO SIMPLE
B40: 02.01.02.02 | C40: CIMIENTO CORRIDO f'c=175 kg/cm2 + 30% P.M. | D40: m3 | H40: vol = | I40: =+J40 -> 17.53 | J40: 17.53
B41: 02.01.02.03 | C41: SOBRECIMIENTO f'c=175 kg/cm2 + 30% P.M. | D41: m3 | H41: vol = | I41: =+J41 -> 9.98 | J41: 9.98
...

Sheet RES. MET. EJEC.
B2: VALORIZACIÓN N° 0 (PERIODO 01 AL 30 DE NOVIEMBRE 2025)
B3: CONTRATISTA | C3: =+FICHA!E4 -> "CONSTRUCCION DE NICHO, COLUMBARIO Y CREMATORIO; REMODELACION DE VELATORIO; EN EL (LA) CEMENTERIO MUNICIPAL EN EL CENTRO POBLADO SANTIAGO DE SURCO, DISTRITO DE SANTIAGO DE SURCO, PROVINCIA LIMA, DEPARTAMENTO LIMA" CUI N| 2658565 - ETAPA COLUMBARIO.
B4: CONTRATISTA | C4: =+FICHA!E9 -> CONSORCIO LIMA
B5: ENTIDAD | C5: MUNICIPALIDAD DISTRITAL DE SANTIAGO DE SURCO
B6: RESIDENTE | C6: =+FICHA!E11 -> ING. GUIDO JAVIER VALVERDE TRUJILLO
B7: SUPERVISOR | C7: =+FICHA!E10 -> ING. JOSE ISMAEL MOSCOSO PINGO
B8: RESUMEN DE METRADOS
B9: ITEM | C9: PARTIDA | D9: UND | H9: METRADO ACTUAL
B14: 01 | C14: OBRAS PROVISIONALES, TRABAJOS PRELIMINARES, SEGURIDAD Y SALUD
B15: 01.01 | C15: OBRAS PROVISIONALES | F15: 1804.51 | G15: =ROUND(E15*F15,2) -> 0 | I15: =+ROUND(H15*F15,2) -> 0
B16: 01.01.01 | C16: CONSTRUCCIONES PROVISIONALES | E16: 3 | F16: 1500 | G16: =ROUND(E16*F16,2) -> 4500 | I16: =+ROUND(H16*F16,2) -> 0
B17: 01.01.01.01 | C17: CARTEL DE IDENTIFICACION DE LA OBRA DE 3.60X2.40 m | D17: und | G17: =SUM(G18:G27) -> 4500 | J17: 1
B18: 01.01.01.02 | C18: CERCO PERIMETRICO PROVISIONAL DE MALLA RASCHELL H=2.10M | D18: m | E18: 1 | F18: 4500 | G18: =ROUND(E18*F18,2) -> 4500 | I18: =+ROUND(H18*F18,2) -> 0 | J18: 48.86
B19: 01.01.01.03 | C19: CERCO PERIMETRICO PROVISIONAL METALICO H=2.10M PROVISIONAL | D19: m | F19: 937.52 | G19: =ROUND(E19*F19,2) -> 0 | I19: =+ROUND(H19*F19,2) -> 0 | J19: 48.86
B20: 01.01.01.04 | C20: ALMACEN, OFICINA Y CASETA DE GUARDIANIA DE TRIPLAY | D20: m2 | J20: 26
B21: 01.01.01.05 | C21: TRANSPORTES DE MAQUINARIAS, EQUIPO Y HERRAMIENTAS A OBRA | D21: glb | J21: 1
B22: 01.01.01.06 | C22: TRANSPORTES DE MATERIALES | D22: glb | J22: 1
B23: 01.01.02 | C23: INSTALACIONES PROVISIONALES
B24: 01.01.02.01 | C24: ALQUILER DE BAÑOS QUIMICOS PORTATILES | D24: mes | J24: 1
B25: 01.01.02.02 | C25: SUM. E INST. PARA EL PUNTO DE AGUA EN OBRA | D25: glb | J25: 1
B26: 01.01.02.03 | C26: SUM. E INST. PARA EL PUNTO DE ENERGIA EN OBRA | D26: glb | J26: 1
B27: 01.01.02.04 | C27: AGUA PROVISIONAL PARA LA CONSTRUCCION | D27: mes | J27: 1
B28: 01.01.02.05 | C28: ENERGIA ELECTRICA PROVISIONAL | D28: mes | J28: 1
B29: 01.02 | C29: TRABAJOS PRELIMINARES
B30: 01.02.01 | C30: CREMATORIO
B31: 01.02.01.01 | C31: DESBROCE Y LIMPIEZA MANUAL DEL TERRENO | D31: m2 | J31: 163
B32: 01.02.01.02 | C32: ELIMINACION DE MALEZA Y ARBUSTOS DE FACIL EXTRACCION | D32: m3 | J32: 28.2
B33: 01.02.03 | C33: COLUMBARIO
B34: 01.02.03.01 | C34: DESBROCE Y LIMPIEZA MANUAL DEL TERRENO | D34: m2 | J34: 188.21
B35: 1.03 | C35: SEGURIDAD Y SALUD EN EL TRABAJO
B36: 01.03.01 | C36: ELABORACIÓN, IMPLEMENTACIÓN Y ADMINISTRACIÓN DEL PLAN DE SEGURIDAD Y SALUD EN EL TRABAJO | D36: glb | J36: 1
B37: 01.03.02 | C37: EQUIPOS DE PROTECCION INDIVIDUAL | D37: glb | J37: 0.25
B38: 01.03.03 | C38: EQUIPOS DE PROTECCION COLECTIVA | D38: glb | J38: 0.25
B39: 01.03.04 | C39: SEÑALIZACIÓN TEMPORAL DE SEGURIDAD | D39: glb | J39: 0.25
B40: 01.03.05 | C40: CAPACITACION EN SEGURIDAD Y SALUD | D40: glb | J40: 0.25
B41: 01.03.06 | C41: RECURSOS PARA RESPUESTAS ANTE EMERGENCIAS | D41: glb | J41: 0.25
B42: 01.04 | C42: PLAN DE MANEJO AMBIENTAL
B43: 01.04.01 | C43: PROGRAMA DE PREVENCION Y MITIGACION AMBIENTAL | D43: glb | J43: 1
B44: 01.05 | C44: TRAZO Y REPLANTEO
B45: 01.05.01 | C45: TRAZO NIVELACION Y REPLANTEO INICIAL | D45: m2 | J45: 405.11
...

Sheet CURVA S
B2: VALORIZACIÓN N° 03 (01 AL 31 DE DICIEMBRE DE 2025)
B4: CURVA "S"
F26: PROGRAMADO | H26: EJECUTADO
F27: % Programado | G27: % programado acum. | H27: % Ejecutado | I27: % ejecutado acum. | N27: % Programado
E28: INICIO | F28: 0 | G28: 0 | H28: 0 | I28: 0 | N28: 0
E29: 45939 | F29: 0.17555412 | G29: =+G28+F29 -> 0.17555412 | H29: 0.2253999 | I29: =+I28+H29 -> 0.2253999 | N29: 0.17555412
E30: 45962 | F30: 0.1778155 | G30: =+G29+F30 -> 0.35336962 | H30: =+H62 -> 0.35859954 | I30: =+I29+H30 -> 0.58399944 | N30: 0.1778155
E31: 45992 | F31: 0.28006745 | G31: =+G30+F31 -> 0.63343707 | H31: =+H63 -> 0.14147619 | I31: =+I30+H31 -> 0.72547563 | N31: 0.28006745
E32: 46023 | F32: 0.21632749 | G32: =+G31+F32 -> 0.84976456 | N32: 0.21632749
E33: 46054 | F33: 0.15023544 | G33: =+G32+F33 -> 1 | N33: 0.15023544
G34: =+G33 -> 1 | I34: =+I31 -> 0.72547563
B36: GRÁFICO DE BARRAS
F58: PROGRAMADO | H58: EJECUTADO
F59: % Programado | G59: % programado acum. | H59: % Ejecutado | I59: % ejecutado acum.
E60: INICIO | F60: 0 | G60: 0 | H60: 0 | I60: 0
E61: 45939 | F61: 0.17555412 | G61: =+G60+F61 -> 0.17555412 | H61: =+'C.G. AVANCE DE OBRA'!J14 -> 0.2253999 | I61: =+I60+H61 -> 0.2253999
E62: 45962 | F62: 0.1778155 | G62: =+G61+F62 -> 0.35336962 | H62: =+'C.G. AVANCE DE OBRA'!J15 -> 0.35859954 | I62: =+I61+H62 -> 0.58399944
E63: 45992 | F63: 0.28006745 | G63: =+G62+F63 -> 0.63343707 | H63: =+'C.G. AVANCE DE OBRA'!J16 -> 0.14147619 | I63: =+I62+H63 -> 0.72547563
E64: 46023 | F64: 0.21632749 | G64: =+G63+F64 -> 0.84976456
E65: 46054 | F65: 0.15023544 | G65: =+G64+F65 -> 1
G66: =+G65 -> 1 | I66: =+I63 -> 0.72547563

Sheet K
A3: CÁLCULO DEL COEFICIENTE DE REAJUSTE
A5: OBRA: | C5: =+FICHA!E4 -> "CONSTRUCCION DE NICHO, COLUMBARIO Y CREMATORIO; REMODELACION DE VELATORIO; EN EL (LA) CEMENTERIO MUNICIPAL EN EL CENTRO POBLADO SANTIAGO DE SURCO, DISTRITO DE SANTIAGO DE SURCO, PROVINCIA LIMA, DEPARTAMENTO LIMA" CUI N| 2658565 - ETAPA COLUMBARIO.
A6: AS Nº | C6: =+FICHA!E15 -> 004-2025-CS-MSS-PRIMERA CONVOCATORIA
A7: ENTIDAD: | C7: =+FICHA!E8 -> MUNICIPALIDAD DISTRITAL DE SANTIAGO DE SURCO
A8: PPTO. BASE | C8: =+FICHA!E20 -> 1730120.8 | E8: INC. IGV
A9: PRESUPUESTO CONTRATADO | C9: =+FICHA!E18 -> 1821179.8 | E9: INC. IGV
A10: FECHA DE PRESUPUESTO BASE | C10: 45536
A12: Formula Polinomica
A13: K = 0.173*(Jr / Jo) + 0.201 *(Ar / Ao) + 0.132*(Cr / Co) + 0.369*(DMr / DMo) + 0.125*GGUr / GGUo)
A16: MONOMIO | B16: IU | C16: DESCRIPCION | D16: SIMBOLO | E16: Coeficiente de Incidencia | F16: % de Participación | G16: Io (OCT-2023) | H16: Ir (MAR.-2024) | I16: Ir (ABR.-2024)
A18: 1 | B18: 47 | C18: MANO DE OBRA INC LEYES SOCIALES | D18: J | E18: 0.173 | F18: 1 | G18: 738.61 | H18: 742.39 | I18: =+ROUND($E18*(H18/$G18)*F18,3) -> 0.174
A19: 2 | B19: 11 | C19: ARTEFACTO ILUMINACION EXTERIOR | D19: AG | E19: 0.201 | F19: 1 | G19: 273.17 | H19: 264.67 | I19: =+ROUND($E19*(H19/$G19)*F19,3) -> 0.195
A20: 3 | B20: 19 | C20: CABLES TIPO NKY-NYY | D20: C | E20: 0.132 | F20: 1 | G20: 1049.03 | H20: 1041.44 | I20: =+ROUND($E20*(H20/$G20)*F20,3) -> 0.131
A21: 4 | B21: 30 | C21: DÓLAR + INFLACION USA | D21: DM | E21: 0.369 | F21: 0.87263 | G21: 689.99 | H21: 671.28 | I21: 0.359
B22: 49 | C22: MAQUINARIA Y EQUIPO IMPORTADO | D22: MD | F22: 0.12737 | G22: 440.33 | H22: 432.41
A23: 5 | B23: 39 | C23: INDICE GENERAL DE PRECIOS AL CONSUMIDOR | D23: GGU | E23: 0.125 | F23: 1 | G23: 558.37 | H23: 568.63 | I23: =+ROUND($E23*(H23/$G23)*F23,3) -> 0.127
D24: K= | E24: =+SUM(E18:E23) -> 1 | I24: =SUM(I18:I23) -> 0.986
B26: *Se usa los IU del mes de agosto porque aún no se publican los IU de septiembre 2023
H29: =H21/G21*F21*0.369 -> 0.313269
H30: =H22/G22*0.369*F22 -> 0.046154172
E31: =H18/G18*E18*F18 -> 0.17388537 | H31: =H29+H30 -> 0.35942317
K33: 5
K34: 13
K35: 48
K36: 30
K37: 39

Sheet Reajuste
A4: CÁLCULO DEL COEFICIENTE DE REAJUSTE
A6: OBRA: | D6: =+K!C5 -> "CONSTRUCCION DE NICHO, COLUMBARIO Y CREMATORIO; REMODELACION DE VELATORIO; EN EL (LA) CEMENTERIO MUNICIPAL EN EL CENTRO POBLADO SANTIAGO DE SURCO, DISTRITO DE SANTIAGO DE SURCO, PROVINCIA LIMA, DEPARTAMENTO LIMA" CUI N| 2658565 - ETAPA COLUMBARIO.
A7: AS Nº | D7: =+K!C6 -> 004-2025-CS-MSS-PRIMERA CONVOCATORIA
A8: ENTIDAD: | D8: =+FICHA!E8 -> MUNICIPALIDAD DISTRITAL DE SANTIAGO DE SURCO
A9: PPTO. BASE | D9: =+FICHA!E18 -> 1821179.8 | F9: INC. IGV
A10: PRESUPUESTO CONTRATADO | D10: =+FICHA!E20 -> 1730120.8 | F10: INC. IGV
A11: PRESUPUESTO CONTRATADO S/IGV | D11: =+D10/1.18 -> 1466204.1 | F11: SIN. IGV
A12: FECHA DE PRESUPUESTO BASE | D12: 45203
A13: Formula Polinomica
B15: K = 0.173*(Jr / Jo) + 0.201 *(Ar / Ao) + 0.132*(Cr / Co) + 0.369*(DMr / DMo) + 0.125*GGUr / GGUo)
F18: R = V * ( K - 1)
A20: MESES | B20: VAL N° | C20: V-REAL | D20: V-PROG | E20: K - 1 | F20: REAJUSTE | G20: REAJUSTE | H20: REAJUSTE | I20: Vr | J20: REAJUSTE
F21: REAL | G21: PROGRAMADO | H21: RECONOCIDO | J21: PAGADO
C22: ( 1 ) | D22: ( 2 ) | E22: ( 3 ) | F22: ( 4 ) = ( 1 ) * ( 3 ) | G22: ( 5 ) = ( 2 ) * ( 3 ) | H22: ( 6 ) | I22: ( 7 ) = ( 1 ) + ( 6 ) | J22: (8)
A24: 45291 | B24: 1 | C24: =+VALO!K565 -> 207432.97 | D24: 569004.97 | E24: =+K!I24-1 -> -0.014 | F24: =+E24*C24 -> -2904.0616 | G24: =+ROUND(E24*D24,2) -> -7966.07 | H24: =+F24 -> -2904.0616 | I24: =ROUND(+C24+H24,2) -> 204528.91 | J24: =+H24 -> -2904.0616
A25: SUB-TOTAL | C25: =SUM(C24:C24) -> 207432.97 | F25: =SUM(F24:F24) -> -2904.0616 | G25: =SUM(G24:G24) -> -7966.07 | H25: =SUM(H24:H24) -> -2904.0616 | J25: 0
C27: CONDICION : | F27: Normal | J27: =SUMA(J24:J24)
C28: Reajuste Acumulado actual : | E28: S/. | F28: =+F29+J25 -> 0
C29: Reajuste Acumulado Anterior : | E29: S/. | F29: 0
C30: Reajuste Presente valorización: | E30: S/. | F30: =+J25 -> 0
E42: V-PROG | F42: V-PROG-MOD
D43: 44136 | E43: =+#REF! -> #REF! | F43: =+E43 -> #REF!
D44: 44166 | E44: =+#REF! -> #REF! | F44: =+E44*22/31 -> #REF!
D45: 44166 | F45: =+E44*0.290322580645161 -> #REF!
D46: 44197 | E46: =+#REF! -> #REF! | F46: =+E46 -> #REF!
D47: 44228 | E47: =+#REF! -> #REF! | F47: =+E47 -> #REF!
D48: 44256 | E48: =+#REF! -> #REF! | F48: =+E48 -> #REF!
D49: 44287 | E49: =+#REF! -> #REF! | F49: =+E49 -> #REF!
E50: =SUM(E43:E49) -> #REF! | F50: =SUM(F43:F49) -> #REF!
A54: 12715.178
